INFO 2020-09-22 18:40:47,290 autoreload 21268 17076 Watching for file changes with StatReloader
INFO 2020-09-22 18:40:49,666 middleware 21268 24296 [36mGET /[0m
INFO 2020-09-22 18:40:49,690 middleware 21268 24296 [35mGET / - 404[0m
WARNING 2020-09-22 18:40:49,690 log 21268 24296 Not Found: /
WARNING 2020-09-22 18:40:49,690 basehttp 21268 24296 "GET / HTTP/1.1" 404 2077
INFO 2020-09-22 18:40:53,686 middleware 21268 24296 [36mGET /test[0m
INFO 2020-09-22 18:40:53,687 middleware 21268 24296 [36mGET /test - 301[0m
INFO 2020-09-22 18:40:53,689 basehttp 21268 24296 "GET /test HTTP/1.1" 301 0
INFO 2020-09-22 18:40:53,704 middleware 21268 24296 [36mGET /test/[0m
ERROR 2020-09-22 18:41:01,597 log 21268 24296 Internal Server Error: /test/
Traceback (most recent call last):
  File "F:\LoggingPOC\logapp\views.py", line 22, in Test
    c='a'/10
TypeError: unsupported operand type(s) for /: 'str' and 'int'

During handling of the above exception, another exception occurred:

Traceback (most recent call last):
  File "E:\PythonHome\lib\site-packages\django\core\handlers\exception.py", line 47, in inner
    response = get_response(request)
  File "E:\PythonHome\lib\site-packages\django\core\handlers\base.py", line 179, in _get_response
    response = wrapped_callback(request, *callback_args, **callback_kwargs)
  File "F:\LoggingPOC\logapp\views.py", line 27, in Test
    sendSimpleMail("Internal Error", 'exc_type',settings.EMAIL_HOST_USER,'durgesh.ccts@gmail.com')
  File "F:\LoggingPOC\logapp\views.py", line 42, in sendSimpleMail
    send_mail(subject,msg, emailfrom, [emailto],fail_silently = False)
  File "E:\PythonHome\lib\site-packages\django\core\mail\__init__.py", line 61, in send_mail
    return mail.send()
  File "E:\PythonHome\lib\site-packages\django\core\mail\message.py", line 284, in send
    return self.get_connection(fail_silently).send_messages([self])
  File "E:\PythonHome\lib\site-packages\django\core\mail\backends\smtp.py", line 102, in send_messages
    new_conn_created = self.open()
  File "E:\PythonHome\lib\site-packages\django\core\mail\backends\smtp.py", line 62, in open
    self.connection = self.connection_class(self.host, self.port, **connection_params)
  File "E:\PythonHome\lib\smtplib.py", line 253, in __init__
    (code, msg) = self.connect(host, port)
  File "E:\PythonHome\lib\smtplib.py", line 339, in connect
    self.sock = self._get_socket(host, port, self.timeout)
  File "E:\PythonHome\lib\smtplib.py", line 308, in _get_socket
    return socket.create_connection((host, port), timeout,
  File "E:\PythonHome\lib\socket.py", line 787, in create_connection
    for res in getaddrinfo(host, port, 0, SOCK_STREAM):
  File "E:\PythonHome\lib\socket.py", line 918, in getaddrinfo
    for res in _socket.getaddrinfo(host, port, family, type, proto, flags):
socket.gaierror: [Errno 11002] getaddrinfo failed
INFO 2020-09-22 18:41:01,643 middleware 21268 24296 [35mGET /test/ - 500[0m
ERROR 2020-09-22 18:41:01,643 basehttp 21268 24296 "GET /test/ HTTP/1.1" 500 109201
INFO 2020-09-22 18:42:32,759 autoreload 21268 17076 F:\LoggingPOC\LoggingPOC\settings.py changed, reloading.
INFO 2020-09-22 18:42:33,605 autoreload 13744 20824 Watching for file changes with StatReloader
INFO 2020-09-22 18:42:35,598 middleware 13744 3008 [36mGET /[0m
INFO 2020-09-22 18:42:35,628 middleware 13744 3008 [35mGET / - 404[0m
WARNING 2020-09-22 18:42:35,628 log 13744 3008 Not Found: /
WARNING 2020-09-22 18:42:35,629 basehttp 13744 3008 "GET / HTTP/1.1" 404 2077
INFO 2020-09-22 18:42:39,442 middleware 13744 3008 [36mGET /test[0m
INFO 2020-09-22 18:42:39,444 middleware 13744 3008 [36mGET /test - 301[0m
INFO 2020-09-22 18:42:39,445 basehttp 13744 3008 "GET /test HTTP/1.1" 301 0
INFO 2020-09-22 18:42:39,467 middleware 13744 3008 [36mGET /test/[0m
ERROR 2020-09-22 18:42:45,171 log 13744 3008 Internal Server Error: /test/
Traceback (most recent call last):
  File "F:\LoggingPOC\logapp\views.py", line 22, in Test
    c='a'/10
TypeError: unsupported operand type(s) for /: 'str' and 'int'

During handling of the above exception, another exception occurred:

Traceback (most recent call last):
  File "E:\PythonHome\lib\site-packages\django\core\handlers\exception.py", line 47, in inner
    response = get_response(request)
  File "E:\PythonHome\lib\site-packages\django\core\handlers\base.py", line 179, in _get_response
    response = wrapped_callback(request, *callback_args, **callback_kwargs)
  File "F:\LoggingPOC\logapp\views.py", line 27, in Test
    sendSimpleMail("Internal Error", 'exc_type',settings.EMAIL_HOST_USER,'durgesh.ccts@gmail.com')
  File "F:\LoggingPOC\logapp\views.py", line 42, in sendSimpleMail
    send_mail(subject,msg, emailfrom, [emailto],fail_silently = False)
  File "E:\PythonHome\lib\site-packages\django\core\mail\__init__.py", line 61, in send_mail
    return mail.send()
  File "E:\PythonHome\lib\site-packages\django\core\mail\message.py", line 284, in send
    return self.get_connection(fail_silently).send_messages([self])
  File "E:\PythonHome\lib\site-packages\django\core\mail\backends\smtp.py", line 102, in send_messages
    new_conn_created = self.open()
  File "E:\PythonHome\lib\site-packages\django\core\mail\backends\smtp.py", line 69, in open
    self.connection.login(self.username, self.password)
  File "E:\PythonHome\lib\smtplib.py", line 734, in login
    raise last_exception
  File "E:\PythonHome\lib\smtplib.py", line 723, in login
    (code, resp) = self.auth(
  File "E:\PythonHome\lib\smtplib.py", line 646, in auth
    raise SMTPAuthenticationError(code, resp)
smtplib.SMTPAuthenticationError: (535, b'5.7.8 Username and Password not accepted. Learn more at\n5.7.8  https://support.google.com/mail/?p=BadCredentials k6sm15074752pfh.92 - gsmtp')
INFO 2020-09-22 18:42:45,219 middleware 13744 3008 [35mGET /test/ - 500[0m
ERROR 2020-09-22 18:42:45,219 basehttp 13744 3008 "GET /test/ HTTP/1.1" 500 104794
INFO 2020-09-22 18:47:40,528 autoreload 13744 20824 F:\LoggingPOC\LoggingPOC\settings.py changed, reloading.
INFO 2020-09-22 18:47:41,327 autoreload 21308 8200 Watching for file changes with StatReloader
INFO 2020-09-22 19:05:52,564 autoreload 21308 8200 F:\LoggingPOC\LoggingPOC\settings.py changed, reloading.
INFO 2020-09-22 19:05:53,454 autoreload 20528 22924 Watching for file changes with StatReloader
INFO 2020-09-22 19:05:56,075 middleware 20528 18172 [36mGET /[0m
INFO 2020-09-22 19:05:56,113 middleware 20528 18172 [35mGET / - 404[0m
WARNING 2020-09-22 19:05:56,113 log 20528 18172 Not Found: /
WARNING 2020-09-22 19:05:56,113 basehttp 20528 18172 "GET / HTTP/1.1" 404 2077
INFO 2020-09-22 19:05:59,599 middleware 20528 18172 [36mGET /test[0m
INFO 2020-09-22 19:05:59,599 middleware 20528 18172 [36mGET /test - 301[0m
INFO 2020-09-22 19:05:59,602 basehttp 20528 18172 "GET /test HTTP/1.1" 301 0
INFO 2020-09-22 19:05:59,632 middleware 20528 18172 [36mGET /test/[0m
INFO 2020-09-22 19:06:06,712 middleware 20528 18172 [36mGET /test/ - 200[0m
INFO 2020-09-22 19:06:06,712 basehttp 20528 18172 "GET /test/ HTTP/1.1" 200 7
INFO 2020-09-22 19:07:07,189 autoreload 20528 22924 F:\LoggingPOC\logapp\views.py changed, reloading.
INFO 2020-09-22 19:07:07,903 autoreload 8452 15448 Watching for file changes with StatReloader
INFO 2020-09-22 19:07:12,251 middleware 8452 2984 [36mGET /[0m
INFO 2020-09-22 19:07:12,291 middleware 8452 2984 [35mGET / - 404[0m
WARNING 2020-09-22 19:07:12,292 log 8452 2984 Not Found: /
WARNING 2020-09-22 19:07:12,293 basehttp 8452 2984 "GET / HTTP/1.1" 404 2077
INFO 2020-09-22 19:07:17,818 middleware 8452 2984 [36mGET /test[0m
INFO 2020-09-22 19:07:17,820 middleware 8452 2984 [36mGET /test - 301[0m
INFO 2020-09-22 19:07:17,820 basehttp 8452 2984 "GET /test HTTP/1.1" 301 0
INFO 2020-09-22 19:07:17,846 middleware 8452 2984 [36mGET /test/[0m
ERROR 2020-09-22 19:07:20,755 log 8452 2984 Internal Server Error: /test/
Traceback (most recent call last):
  File "F:\LoggingPOC\logapp\views.py", line 22, in Test
    c='a'/10
TypeError: unsupported operand type(s) for /: 'str' and 'int'

During handling of the above exception, another exception occurred:

Traceback (most recent call last):
  File "E:\PythonHome\lib\site-packages\django\core\handlers\exception.py", line 47, in inner
    response = get_response(request)
  File "E:\PythonHome\lib\site-packages\django\core\handlers\base.py", line 179, in _get_response
    response = wrapped_callback(request, *callback_args, **callback_kwargs)
  File "F:\LoggingPOC\logapp\views.py", line 27, in Test
    sendSimpleMail("Internal Error", exc_type,settings.EMAIL_HOST_USER,'durgesh.ccts@gmail.com')
  File "F:\LoggingPOC\logapp\views.py", line 42, in sendSimpleMail
    send_mail(subject,msg, emailfrom, [emailto],fail_silently = False)
  File "E:\PythonHome\lib\site-packages\django\core\mail\__init__.py", line 61, in send_mail
    return mail.send()
  File "E:\PythonHome\lib\site-packages\django\core\mail\message.py", line 284, in send
    return self.get_connection(fail_silently).send_messages([self])
  File "E:\PythonHome\lib\site-packages\django\core\mail\backends\smtp.py", line 109, in send_messages
    sent = self._send(message)
  File "E:\PythonHome\lib\site-packages\django\core\mail\backends\smtp.py", line 123, in _send
    message = email_message.message()
  File "E:\PythonHome\lib\site-packages\django\core\mail\message.py", line 246, in message
    msg = SafeMIMEText(self.body, self.content_subtype, encoding)
  File "E:\PythonHome\lib\site-packages\django\core\mail\message.py", line 159, in __init__
    MIMEText.__init__(self, _text, _subtype=_subtype, _charset=_charset)
  File "E:\PythonHome\lib\email\mime\text.py", line 42, in __init__
    self.set_payload(_text, _charset)
  File "E:\PythonHome\lib\site-packages\django\core\mail\message.py", line 169, in set_payload
    for line in payload.splitlines()
AttributeError: type object 'TypeError' has no attribute 'splitlines'
INFO 2020-09-22 19:07:20,787 middleware 8452 2984 [35mGET /test/ - 500[0m
ERROR 2020-09-22 19:07:20,787 basehttp 8452 2984 "GET /test/ HTTP/1.1" 500 103098
